Workbook
Name Slicer_Bank_Name: #N/A
Name Slicer_Payment_Mode: #N/A
Name Slicer_short_month_name: #N/A

Sheet Dashboard
A2: u
A3: #VALUE!
H34: vuuū

Sheet Sheet2
A1: Transaction_Type | B1: Investment | C1: Transaction_Type | D1: Income | F1: Count of Transaction_ID
F2: 1623
A3: Total Expenses | C3: Avg Transaction
A4: 2756061.7 | C4: 62151.458
A5: Transaction_Type | B5: Income | F5: Transaction_Type | G5: Income
A7: Total Investment | C7: Average of Monthly_Budget | F7: Row Labels | G7: Sum of Amount
A8: 18707589 | C8: 49884.791 | F8: Dividends | G8: 3533752.9
F9: Freelance | G9: 4492579.9
A10: Transaction_Type | B10: Income | F10: Interest | G10: 4006442.8
F11: Rental Income | G11: 3509842.9
A12: Total income | F12: Salary | G12: 3164970.3
A13: 18707589 | F13: Grand Total | G13: 18707589
A29: Transaction_Type | B29: Income
A31: Row Labels | B31: Sum of income | D31: Row Labels | E31: Sum of Amount
A32: January | B32: 20130316 | D32: Dividends | E32: 3533752.9
A33: February | B33: 17202065 | D33: Freelance | E33: 4492579.9
A34: March | B34: 20705970 | D34: Interest | E34: 4006442.8
A35: April | B35: 18707589 | D35: Rental Income | E35: 3509842.9
A36: May | B36: 22708136 | D36: Salary | E36: 3164970.3
A37: June | B37: 19685103 | D37: Grand Total | E37: 18707589
A38: July | B38: 19410369
A39: August | B39: 20739251
A40: September | B40: 19771136
A41: October | B41: 18835264
A42: November | B42: 20137380
A43: December | B43: 22095932
A44: Grand Total | B44: 2.4012851e+08

Sheet resource
I1: Month | J1: x | K1: indent | L1: income | M1: expenses | N1: indent c
I2: January | J2: =LEFT(I2,3) -> Jan | K2: =K14 -> 908325.44 | L2: =Sheet2!B32 -> 20130316 | M2: =Sheet2!E32 -> 3533752.9 | N2: =K2 -> 908325.44
I3: February | J3: =LEFT(I3,3) -> Feb | K3: =K14 -> 908325.44 | L3: =Sheet2!B33 -> 17202065 | M3: =Sheet2!E33 -> 4492579.9 | N3: =K3 -> 908325.44
I4: March | J4: =LEFT(I4,3) -> Mar | K4: =K14 -> 908325.44 | L4: =Sheet2!B34 -> 20705970 | M4: =Sheet2!E34 -> 4006442.8 | N4: =K4 -> 908325.44
I5: April | J5: =LEFT(I5,3) -> Apr | K5: =K14 -> 908325.44 | L5: =Sheet2!B35 -> 18707589 | M5: =Sheet2!E35 -> 3509842.9 | N5: =K5 -> 908325.44
I6: May | J6: =LEFT(I6,3) -> May | K6: =K14 -> 908325.44 | L6: =Sheet2!B36 -> 22708136 | M6: =Sheet2!E36 -> 3164970.3 | N6: =K6 -> 908325.44
I7: June | J7: =LEFT(I7,3) -> Jun | K7: =K14 -> 908325.44 | L7: =Sheet2!B37 -> 19685103 | M7: =Sheet2!E37 -> 18707589 | N7: =K7 -> 908325.44
I8: July | J8: =LEFT(I8,3) -> Jul | K8: =K14 -> 908325.44 | L8: =Sheet2!B38 -> 19410369 | M8: =Sheet2!E38 -> 0 | N8: =K8 -> 908325.44
I9: August | J9: =LEFT(I9,3) -> Aug | K9: =K14 -> 908325.44 | L9: =Sheet2!B39 -> 20739251 | M9: =Sheet2!E39 -> 0 | N9: =K9 -> 908325.44
I10: September | J10: =LEFT(I10,3) -> Sep | K10: =K14 -> 908325.44 | L10: =Sheet2!B40 -> 19771136 | M10: =Sheet2!E40 -> 0 | N10: =K10 -> 908325.44
I11: October | J11: =LEFT(I11,3) -> Oct | K11: =K14 -> 908325.44 | L11: =Sheet2!B41 -> 18835264 | M11: =Sheet2!E41 -> 0 | N11: =K11 -> 908325.44
I12: November | J12: =LEFT(I12,3) -> Nov | K12: =K14 -> 908325.44 | L12: =Sheet2!B42 -> 20137380 | M12: =Sheet2!E42 -> 0 | N12: =K12 -> 908325.44
I13: December | J13: =LEFT(I13,3) -> Dec | K13: =K14 -> 908325.44 | L13: =Sheet2!B43 -> 22095932 | M13: =Sheet2!E43 -> 0 | N13: =K13 -> 908325.44
K14: =MAX(L2:M13)*4% -> 908325.44 | N14: =K14 -> 908325.44
B19: Transaction_Type | C19: Income
B21: Row Labels | C21: Sum of Amount | E21: Row Labels | F21: Count of Transaction_ID | H21: Row Labels | I21: Average of Available_Bank_Balance
B22: Dividends | C22: 3533752.9 | E22: Cash | F22: 294 | H22: Axis Bank | I22: 182341.07
B23: Freelance | C23: 4492579.9 | E23: Credit Card | F23: 344 | H23: HDFC Bank | I23: 175118.72
B24: Interest | C24: 4006442.8 | E24: Debit Card | F24: 310 | H24: ICICI Bank | I24: 179969.52
B25: Rental Income | C25: 3509842.9 | E25: Net Banking | F25: 335 | H25: Kotak Mahindra | I25: 182785.02
B26: Salary | C26: 3164970.3 | E26: UPI | F26: 340 | H26: State Bank of India | I26: 165269.89
B27: Grand Total | C27: 18707589 | E27: Grand Total | F27: 1623 | H27: Grand Total | I27: 176804.81
I32: Transaction_Type | J32: (All)
C34: Sum of Amount | D34: Column Labels | I34: Row Labels | J34: Sum of Amount
C35: Row Labels | D35: Expense | E35: Income | F35: Investment | G35: Grand Total | I35: Ahmedabad | J35: 3311789.2
C36: Jan | D36: 8991480.4 | E36: 20130316 | F36: 2955101.9 | G36: 32076898 | I36: Bangalore | J36: 3168950.1
C37: Feb | D37: 8122347.3 | E37: 17202065 | F37: 2673396.5 | G37: 27997808 | I37: Chennai | J37: 3023974.7
C38: Mar | D38: 8368362.8 | E38: 20705970 | F38: 2840203.1 | G38: 31914536 | I38: Delhi | J38: 3245514.5
C39: Apr | D39: 9082684.8 | E39: 18707589 | F39: 2756061.7 | G39: 30546335 | I39: Hyderabad | J39: 2859794.6
C40: May | D40: 8821484 | E40: 22708136 | F40: 3071493.4 | G40: 34601113 | I40: Jaipur | J40: 2977309.2
C41: Jun | D41: 8422107.8 | E41: 19685103 | F41: 2942395.2 | G41: 31049606 | I41: Kolkata | J41: 3101488.5
C42: Jul | D42: 9200967.8 | E42: 19410369 | F42: 3198486.6 | G42: 31809823 | I42: Mumbai | J42: 2696127.9
C43: Aug | D43: 8913294.6 | E43: 20739251 | F43: 2942692.9 | G43: 32595238 | I43: Pune | J43: 3347548.2
C44: Sep | D44: 8458021.9 | E44: 19771136 | F44: 2543477.8 | G44: 30772636 | I44: Surat | J44: 2813838.5
C45: Oct | D45: 8970134.6 | E45: 18835264 | F45: 3295988.7 | G45: 31101387 | I45: Grand Total | J45: 30546335
C46: Nov | D46: 8777066.4 | E46: 20137380 | F46: 3003809.8 | G46: 31918256
C47: Dec | D47: 9635678.8 | E47: 22095932 | F47: 3391610.6 | G47: 35123222
C48: Grand Total | D48: 1.0576363e+08 | E48: 2.4012851e+08 | F48: 35614718 | G48: 3.8150686e+08
A54: Payment_Mode | B54: (All)
A56: Average of Available_Bank_Balance
...

Sheet Indian_Finance_Investment_Budge
A1: Transaction_ID | B1: Date | C1: Customer_Name | D1: Transaction_Type | E1: Category | F1: Merchant | G1: Amount | H1: Payment_Mode | I1: Bank_Name | J1: Location | K1: Monthly_Budget | L1: Available_Bank_Balance | M1: Month Name | N1: short month name
A2: TXN-200000 | B2: 45088 | C2: Riya Sharma | D2: Expense | E2: Entertainment | F2: HDFC Bank | G2: 10882.94 | H2: Cash | I2: Kotak Mahindra | J2: Hyderabad | K2: 63237.79 | L2: 77414.13 | M2: June | N2: Jun
A3: TXN-200001 | B3: 45010 | C3: Aadhya Iyer | D3: Expense | E3: Food & Dining | F3: Bescom | G3: 13997.78 | H3: Debit Card | I3: Kotak Mahindra | J3: Pune | K3: 41199.42 | L3: 76715.06 | M3: March | N3: Mar
A4: TXN-200002 | B4: 45128 | C4: Pari Kapoor | D4: Expense | E4: Groceries | F4: BigBasket | G4: 5568.8 | H4: Cash | I4: State Bank of India | J4: Ahmedabad | K4: 53767.91 | L4: 56067.89 | M4: July | N4: Jul
A5: TXN-200003 | B5: 44928 | C5: Aditya Sharma | D5: Investment | E5: Crypto | F5: MakeMyTrip | G5: 19196.18 | H5: Cash | I5: HDFC Bank | J5: Bangalore | K5: 65207.05 | L5: 56455.72 | M5: January | N5: Jan
A6: TXN-200004 | B6: 44940 | C6: Ananya Sharma | D6: Expense | E6: Medical | F6: Flipkart | G6: 12174.04 | H6: UPI | I6: ICICI Bank | J6: Hyderabad | K6: 35460.58 | L6: 139207.04 | M6: January | N6: Jan
A7: TXN-200005 | B7: 44937 | C7: Anika Malhotra | D7: Expense | E7: Travel | F7: Reliance Smart | G7: 8636.07 | H7: Debit Card | I7: Axis Bank | J7: Jaipur | K7: 69128.99 | L7: 160553.27 | M7: January | N7: Jan
A8: TXN-200006 | B8: 45198 | C8: Ananya Patel | D8: Expense | E8: Shopping | F8: Bescom | G8: 11778.88 | H8: Cash | I8: HDFC Bank | J8: Pune | K8: 49292.57 | L8: 131158.2 | M8: September | N8: Sep
A9: TXN-200007 | B9: 45035 | C9: Shaurya Singh | D9: Income | E9: Salary | F9: Employer/Client | G9: 41129.83 | H9: Cash | I9: ICICI Bank | J9: Pune | K9: 37230.24 | L9: 202003.33 | M9: April | N9: Apr
A10: TXN-200008 | B10: 44947 | C10: Reyansh Verma | D10: Expense | E10: Medical | F10: BigBasket | G10: 7275.2 | H10: Debit Card | I10: ICICI Bank | J10: Pune | K10: 56124.14 | L10: 134289.33 | M10: January | N10: Jan
A11: TXN-200009 | B11: 44983 | C11: Saanvi Gupta | D11: Expense | E11: Utilities | F11: BigBasket | G11: 9665.62 | H11: UPI | I11: Kotak Mahindra | J11: Ahmedabad | K11: 56512.16 | L11: 102088.63 | M11: February | N11: Feb
A12: TXN-200010 | B12: 45237 | C12: Aaryan Kapoor | D12: Expense | E12: Medical | F12: Amazon.in | G12: 6174.43 | H12: UPI | I12: ICICI Bank | J12: Ahmedabad | K12: 63365.86 | L12: 58582.98 | M12: November | N12: Nov
A13: TXN-200011 | B13: 45084 | C13: Diya Gupta | D13: Income | E13: Freelance | F13: Employer/Client | G13: 50741.86 | H13: UPI | I13: HDFC Bank | J13: Chennai | K13: 47392.82 | L13: 237334.82 | M13: June | N13: Jun
... A20001: TXN-219999 | B20001: 45148 | C20001: Shaurya Patel | D20001: Expense | E20001: Utilities | F20001: Zomato | G20001: 9577.92 | H20001: Credit Card | I20001: Axis Bank | J20001: Bangalore | K20001: 46888.9 | L20001: 172608.29 | M20001: August | N20001: Aug
